Workbook
Name \a: #REF!
Name \a: #REF!
Name \a: #REF!
Name \a: #REF!
Name \a: #REF!
Name \a: #REF!
Name \a: #REF!
Name \a: #REF!
Name \a: #REF!
Name \a: #REF!
Name \a: #REF!
Name \a: #REF!
Name \a: #REF!

Sheet cases2
A1: Case에 상관없이 해당 업체가 속하는 산업분류를 입력해야됨
A4: Case2 | B4: 매출액을 알고 원가의 일부를 알고 있을때
A6: 매출액 | B6: 1000
A8: 원가구조
C9: 비중(100%) | D9: 금액 | F9: scope1 | G9: =B6*Ad!J42 -> 224.85881
A10: A | B10: 농림수산품 | F10: scope2 | G10: =B6*M!J24 -> 498.2753
A11: B | B11: 광산품 | F11: scope3 | G11: =B6*M!J41-cases2!G9-cases2!G10 -> 168.06666
A12: C01 | B12: 음식료품 | F12: 계 | G12: =SUM(G9:G11) -> 891.20078
A13: C02 | B13: 섬유 및 가죽제품
A14: C03 | B14: 목재 및 종이, 인쇄 | G14: 자부문 및 타업종 유발(산업별) | I14: 배출량
A15: C04 | B15: 석탄 및 석유제품 | G15: A | H15: 농림수산품 | I15: =$B$6*M!J7 -> 1.810923
A16: C05 | B16: 화학제품 | G16: B | H16: 광산품 | I16: =$B$6*M!J8 -> 0.34356144
A17: C06 | B17: 비금속광물제품 | G17: C01 | H17: 음식료품 | I17: =$B$6*M!J9 -> 0.15694193
A18: C07 | B18: 1차 금속제품 | G18: C02 | H18: 섬유 및 가죽제품 | I18: =$B$6*M!J10 -> 0.39327281
A19: C08 | B19: 금속가공제품 | G19: C03 | H19: 목재 및 종이, 인쇄 | I19: =$B$6*M!J11 -> 0.66717961
A20: C09 | B20: 컴퓨터, 전자 및 광학기기 | G20: C04 | H20: 석탄 및 석유제품 | I20: =$B$6*M!J12 -> 8.9860547
A21: C10 | B21: 전기장비 | G21: C05 | H21: 화학제품 | I21: =$B$6*M!J13 -> 37.913885
A22: C11 | B22: 기계 및 장비 | C22: 10 | D22: =C22*$B$6/100 -> 100 | H22: 분석업체 | I22: =$B$6*M!J14 -> 288.28063
A23: C12 | B23: 운송장비 | G23: C06 | H23: 비금속광물제품 | I23: =$B$6*M!J15 -> 2.6139488
A24: C13 | B24: 기타 제조업 제품 | G24: C07 | H24: 1차 금속제품 | I24: =$B$6*M!J16 -> 11.318045
A25: C14 | B25: 제조임가공 및 산업용 장비 수리 | G25: C08 | H25: 금속가공제품 | I25: =$B$6*M!J17 -> 0.072294766
A26: D | B26: 전력, 가스 및 증기 | C26: 20 | D26: =C26*$B$6/100 -> 200 | G26: C09 | H26: 컴퓨터, 전자 및 광학기기 | I26: =$B$6*M!J18 -> 0.20127127
A27: E | B27: 수도, 폐기물처리 및 재활용서비스 | G27: C10 | H27: 전기장비 | I27: =$B$6*M!J19 -> 0.013017723
A28: F | B28: 건설 | G28: C11 | H28: 기계 및 장비 | I28: =$B$6*M!J20 -> 3.9221817
A29: G | B29: 도소매 및 상품중개서비스 | G29: C12 | H29: 운송장비 | I29: =$B$6*M!J21 -> 0.061659999
A30: H | B30: 운송서비스 | G30: C13 | H30: 기타 제조업 제품 | I30: =$B$6*M!J22 -> 0.20549766
A31: I | B31: 음식점 및 숙박서비스 | G31: C14 | H31: 제조임가공 및 산업용 장비 수리 | I31: =$B$6*M!J23 -> 0.75005313
A32: J | B32: 정보통신 및 방송 서비스 | G32: D | H32: 전력, 가스 및 증기 | I32: =$B$6*M!J24 -> 498.2753
A33: K | B33: 금융 및 보험 서비스 | G33: E | H33: 수도, 폐기물처리 및 재활용서비스 | I33: =$B$6*M!J25 -> 8.3330607
A34: L | B34: 부동산서비스 | G34: F | H34: 건설 | I34: =$B$6*M!J26 -> 0.014906132
A35: M | B35: 전문, 과학 및 기술 서비스 | G35: G | H35: 도소매 및 상품중개서비스 | I35: =$B$6*M!J27 -> 0.265361
A36: N | B36: 사업지원서비스 | G36: H | H36: 운송서비스 | I36: =$B$6*M!J28 -> 25.806609
A37: O | B37: 공공행정, 국방 및 사회보장 | G37: I | H37: 음식점 및 숙박서비스 | I37: =$B$6*M!J29 -> 0.17438294
A38: P | B38: 교육서비스 | G38: J | H38: 정보통신 및 방송 서비스 | I38: =$B$6*M!J30 -> 0.0069804421
... A42: T | B42: 기타 | G42: N | H42: 사업지원서비스 | I42: =$B$6*M!J34 -> 0.024009879
A43: 9590 | B43: 중간투입계 | C43: =SUM(C10:C42) -> 30 | D43: =C43*$B$6/100 -> 300 | G43: O | H43: 공공행정, 국방 및 사회보장 | I43: =$B$6*M!J35 -> 0.090332699
A44: 9610 | B44: 피용자보수 | C44: 20 | D44: =C44*$B$6/100 -> 200 | G44: P | H44: 교육서비스 | I44: =$B$6*M!J36 -> 0.01518201
A45: 9621 | B45: 영업이익(영업잉여) | C45: 10 | D45: =C45*$B$6/100 -> 100 | G45: Q | H45: 보건 및 사회복지 서비스 | I45: =$B$6*M!J37 -> 0.014657314
A46: 9622 | B46: 감가상각비(고정자본소모) | C46: 5 | D46: =C46*$B$6/100 -> 50 | G46: R | H46: 예술, 스포츠 및 여가 관련 서비스 | I46: =$B$6*M!J38 -> 0.015353923
A47: 9630 | B47: 생산세(보조금공제) | C47: 미기재 | G47: S | H47: 기타 서비스 | I47: =$B$6*M!J39 -> 0.023085859
...

Sheet A표_총거래표(생산자)_원본
A1: 투입산출표_총거래표(2023년 가격)
A2: 2023년
A3: 생산자가격
A4: 단위 : 백만원
A5: 상품 상품 | C5: A | D5: B | E5: C01 | F5: C02 | G5: C03 | H5: C04 | I5: C05 | J5: C06 | K5: C07 | L5: C08 | M5: C09 | N5: C10 | O5: C11 | P5: C12 | Q5: C13 | R5: C14 | S5: D | T5: E | U5: F | V5: G | W5: H | X5: I | Y5: J | Z5: K | AA5: L | AB5: M | AC5: N | AD5: O | AE5: P | AF5: Q | AG5: R | AH5: S | AI5: T | AJ5: 9090 | AK5: 9111 | AL5: 9112 | AM5: 9121 | AN5: 9122 | AO5: 9131 | AP5: 9132 | AQ5: 9140 | AR5: 9190 | AS5: 9290 | AT5: 9310 | AU5: 9321 | AV5: 9322 | AW5: 9329 | AX5: 9331 | AY5: 9332 | AZ5: 9390
C6: 농림수산품 | D6: 광산품 | E6: 음식료품 | F6: 섬유 및 가죽제품 | G6: 목재 및 종이, 인쇄 | H6: 석탄 및 석유제품 | I6: 화학제품 | J6: 비금속광물제품 | K6: 1차 금속제품 | L6: 금속가공제품 | M6: 컴퓨터, 전자 및 광학기기 | N6: 전기장비 | O6: 기계 및 장비 | P6: 운송장비 | Q6: 기타 제조업제품 | R6: 제조임가공 및 산업용 장비 수리 | S6: 전력, 가스 및 증기 | T6: 수도, 폐기물처리 및 재활용서비스 | U6: 건설 | V6: 도소매 및 상품중개서비스 | W6: 운송서비스 | X6: 음식점 및 숙박서비스 | Y6: 정보통신 및 방송서비스 | Z6: 금융 및 보험서비스 | AA6: 부동산서비스 | AB6: 전문, 과학 및 기술 서비스 | AC6: 사업지원서비스 | AD6: 공공행정, 국방 및 사회보장 | AE6: 교육서비스 | AF6: 보건 및 사회복지서비스 | AG6: 예술, 스포츠 및 여가 관련 서비스 | AH6: 기타 서비스 | AI6: 기타 | AJ6: 중간수요계 | AK6: 민간소비지출 (가계 및 가계봉사 비영리단체) | AL6: 정부소비지출 | AM6: 민간고정 자본형성 | AN6: 정부고정 자본형성 | AO6: 재고증감 | AP6: 귀중품 순취득 | AQ6: 수출 | AR6: 최종수요계 | AS6: 총수요계 | AT6: 총산출 | AU6: 수입 | AV6: 생산물세(수입) | AW6: 수입계 | AX6: 도소매마진 | AY6: 화물운임 | AZ6: 총공급계 | BA6: 수입비중
A7: A | B7: 농림수산품 | C7: 4256311 | D7: 3473 | E7: 44787107 | F7: 264444 | G7: 661849 | H7: 4203 | I7: 1326559 | J7: 3614 | K7: 6461 | L7: 7383 | M7: 7338 | N7: 2082 | O7: 6967 | P7: 2432 | Q7: 14838 | R7: 542287 | S7: 3751 | T7: 12739 | U7: 403188 | V7: 103863 | W7: 13100 | X7: 13418941 | Y7: 14422 | Z7: 11833 | AA7: 7087 | AB7: 72958 | AC7: 20574 | AD7: 333297 | AE7: 716622 | AF7: 904970 | AG7: 72052 | AH7: 72609 | AI7: 3405 | AJ7: 68082759 | AK7: 20977330 | AL7: 0 | AM7: 1005548 | AN7: 708 | AO7: -196797 | AP7: 0 | AQ7: 1148216 | AR7: 22935005 | AS7: 91017764 | AT7: 74068069 | AU7: 16390900 | AV7: 558795 | AW7: 16949695 | AX7: 0 | AY7: 0 | AZ7: 91017764
A8: B | B8: 광산품 | C8: 2055 | D8: 2999 | E8: 48702 | F8: 3592 | G8: 35023 | H8: 108067377 | I8: 8679207 | J8: 5208178 | K8: 33232955 | L8: 40482 | M8: 37583 | N8: 8789 | O8: 16354 | P8: 5802 | Q8: 3785 | R8: 76904 | S8: 68593275 | T8: 53587 | U8: 278992 | V8: 0 | W8: 0 | X8: 15310 | Y8: 0 | Z8: 0 | AA8: 141 | AB8: 17244 | AC8: 13414 | AD8: 16766 | AE8: 1073 | AF8: 16722 | AG8: 2420 | AH8: 2421 | AI8: 34 | AJ8: 224481186 | AK8: 20312 | AL8: 0 | AM8: 0 | AN8: 0 | AO8: -1208060 | AP8: 0 | AQ8: 164539 | AR8: -1023209 | AS8: 223457977 | AT8: 5326597 | AU8: 213114501 | AV8: 5016879 | AW8: 218131380 | AX8: 0 | AY8: 0 | AZ8: 223457977
A9: C01 | B9: 음식료품 | C9: 13490896 | D9: 16188 | E9: 37267582 | F9: 1267831 | G9: 87762 | H9: 29747 | I9: 1948954 | J9: 32354 | K9: 78230 | L9: 106035 | M9: 28458 | N9: 23722 | O9: 80841 | P9: -15144 | Q9: 10976 | R9: 642150 | S9: 1667262 | T9: 75594 | U9: 29879 | V9: 2137267 | W9: 237559 | X9: 62634265 | Y9: 321736 | Z9: 166231 | AA9: 20690 | AB9: 1680284 | AC9: 730059 | AD9: 1178818 | AE9: 3190985 | AF9: 3326884 | AG9: 2766615 | AH9: 1099495 | AI9: 54767 | AJ9: 136414972 | AK9: 79996863 | AL9: 0 | AM9: 0 | AN9: 0 | AO9: -312055 | AP9: 0 | AQ9: 13216832 | AR9: 92901640 | AS9: 229316612 | AT9: 182394945 | AU9: 42877588 | AV9: 4044079 | AW9: 46921667 | AX9: 0 | AY9: 0 | AZ9: 229316612
A10: C02 | B10: 섬유 및 가죽제품 | C10: 690669 | D10: 18761 | E10: 152583 | F10: 21941986 | G10: 610886 | H10: 100196 | I10: 1674120 | J10: 167311 | K10: 181532 | L10: 398657 | M10: 396591 | N10: 175855 | O10: 148702 | P10: 1234584 | Q10: 1704538 | R10: 2681541 | S10: 46471 | T10: 260471 | U10: 183767 | V10: 1793848 | W10: 1945331 | X10: 1580633 | Y10: 250655 | Z10: 107312 | AA10: 175614 | AB10: 554339 | AC10: 1178436 | AD10: 689348 | AE10: 212655 | AF10: 919104 | AG10: 556457 | AH10: 863694 | AI10: 17447 | AJ10: 43614094 | AK10: 44692848 | AL10: 0 | AM10: 99316 | AN10: 49995 | AO10: 238347 | AP10: 0 | AQ10: 20177963 | AR10: 65258469 | AS10: 108872563 | AT10: 70160146 | AU10: 35870234 | AV10: 2842183 | AW10: 38712417 | AX10: 0 | AY10: 0 | AZ10: 108872563
A11: C03 | B11: 목재 및 종이, 인쇄 | C11: 866017 | D11: 11121 | E11: 3715108 | F11: 415547 | G11: 17244503 | H11: 134210 | I11: 1997375 | J11: 426375 | K11: 243459 | L11: 1061021 | M11: 295987 | N11: 571350 | O11: 353312 | P11: 120280 | Q11: 1901882 | R11: 408384 | S11: 792752 | T11: -6870 | U11: 6049727 | V11: 4278205 | W11: 1476571 | X11: 2137353 | Y11: 2006707 | Z11: 1592341 | AA11: 227894 | AB11: 5069685 | AC11: 631911 | AD11: 913133 | AE11: 960333 | AF11: 1291250 | AG11: 308585 | AH11: 831503 | AI11: 9881 | AJ11: 58336892 | AK11: 1990283 | AL11: 0 | AM11: 0 | AN11: 0 | AO11: 247498 | AP11: 0 | AQ11: 4630328 | AR11: 6868109 | AS11: 65205001 | AT11: 56014686 | AU11: 8967588 | AV11: 222727 | AW11: 9190315 | AX11: 0 | AY11: 0 | AZ11: 65205001
A12: C04 | B12: 석탄 및 석유제품 | C12: 1553720 | D12: 127562 | E12: 368746 | F12: 182073 | G12: 306192 | H12: 8485744 | I12: 43895247 | J12: 2409467 | K12: 721361 | L12: 527953 | M12: 108255 | N12: 512348 | O12: 337756 | P12: 472866 | Q12: 45874 | R12: 1013019 | S12: 4111860 | T12: 690962 | U12: 4687554 | V12: 9503880 | W12: 24628899 | X12: 3477744 | Y12: 404311 | Z12: 146259 | AA12: 918026 | AB12: 4380042 | AC12: 918546 | AD12: 3355174 | AE12: 2599025 | AF12: 1564184 | AG12: 353775 | AH12: 1093548 | AI12: 22523 | AJ12: 123924495 | AK12: 20010215 | AL12: 0 | AM12: 0 | AN12: 0 | AO12: 685143 | AP12: 0 | AQ12: 77066088 | AR12: 97761446 | AS12: 221685941 | AT12: 176562966 | AU12: 44170694 | AV12: 952281 | AW12: 45122975 | AX12: 0 | AY12: 0 | AZ12: 221685941
A13: C05 | B13: 화학제품 | C13: 5335756 | D13: 219298 | E13: 4720446 | F13: 6819729 | G13: 3803170 | H13: 3537795 | I13: 129362837 | J13: 2543485 | K13: 3102895 | L13: 9009090 | M13: 20188581 | N13: 17404850 | O13: 5570490 | P13: 21793941 | Q13: 2998181 | R13: 1983061 | S13: 2417171 | T13: 2164833 | U13: 12222208 | V13: 5288979 | W13: 1560674 | X13: 4858345 | Y13: 812354 | Z13: 121602 | AA13: 277568 | AB13: 10278206 | AC13: 3992188 | AD13: 1614775 | AE13: 1270286 | AF13: 32946431 | AG13: 758170 | AH13: 3728706 | AI13: 31956 | AJ13: 322738057 | AK13: 16391860 | AL13: 0 | AM13: 0 | AN13: 0 | AO13: 2035871 | AP13: 0 | AQ13: 141937188 | AR13: 160364919 | AS13: 483102976 | AT13: 376626218 | AU13: 104125789 | AV13: 2350969 | AW13: 106476758 | AX13: 0 | AY13: 0 | AZ13: 483102976
A14: C06 | B14: 비금속광물제품 | C14: 36617 | D14: 8918 | E14: 905256 | F14: 41584 | G14: 59557 | H14: 153911 | I14: 1621305 | J14: 7622593 | K14: 3265699 | L14: 612991 | M14: 1987167 | N14: 1806637 | O14: 511290 | P14: 2300485 | Q14: 257029 | R14: 203556 | S14: -152005 | T14: 187593 | U14: 29763706 | V14: 119481 | W14: 76745 | X14: 742147 | Y14: 13661 | Z14: 3896 | AA14: 84202 | AB14: 340999 | AC14: 226159 | AD14: 331107 | AE14: 142765 | AF14: 71373 | AG14: 141732 | AH14: 56146 | AI14: 4568 | AJ14: 53548870 | AK14: 181273 | AL14: 0 | AM14: 0 | AN14: 0 | AO14: 187387 | AP14: 0 | AQ14: 4781328 | AR14: 5149988 | AS14: 58698858 | AT14: 50827524 | AU14: 7600425 | AV14: 270909 | AW14: 7871334 | AX14: 0 | AY14: 0 | AZ14: 58698858
A15: C07 | B15: 1차 금속제품 | C15: 91111 | D15: 8196 | E15: 26239 | F15: 2697 | G15: 45720 | H15: 562107 | I15: 3388712 | J15: 903550 | K15: 62564642 | L15: 26175296 | M15: 6708120 | N15: 18310513 | O15: 13493061 | P15: 26369922 | Q15: 1765850 | R15: 1069388 | S15: 413958 | T15: 170727 | U15: 25701309 | V15: -713 | W15: 132195 | X15: 27276 | Y15: -21236 | Z15: -69 | AA15: -534 | AB15: 435186 | AC15: 1189 | AD15: 3109 | AE15: -19677 | AF15: 366089 | AG15: -4842 | AH15: -29801 | AI15: 9136 | AJ15: 188668426 | AK15: -731720 | AL15: 0 | AM15: -3134918 | AN15: -83309 | AO15: 118320 | AP15: 163833 | AQ15: 59288136 | AR15: 55620342 | AS15: 244288768 | AT15: 191899112 | AU15: 52115731 | AV15: 273925 | AW15: 52389656 | AX15: 0 | AY15: 0 | AZ15: 244288768
A16: C08 | B16: 금속가공제품 | C16: 77940 | D16: 117861 | E16: 2371080 | F16: 248175 | G16: 609407 | H16: 2900135 | I16: 2673621 | J16: 667203 | K16: 1573739 | L16: 20929812 | M16: 2705363 | N16: 5224767 | O16: 19768968 | P16: 18833190 | Q16: 1490999 | R16: 1288202 | S16: 869133 | T16: 548021 | U16: 25476298 | V16: 1147254 | W16: 1077767 | X16: 1741987 | Y16: 251710 | Z16: 141513 | AA16: 200822 | AB16: 1247365 | AC16: 1101443 | AD16: 1742143 | AE16: 474147 | AF16: 355816 | AG16: 255624 | AH16: 953188 | AI16: 15794 | AJ16: 119080487 | AK16: 1887217 | AL16: 0 | AM16: 6527800 | AN16: 2370938 | AO16: 174696 | AP16: 0 | AQ16: 17376557 | AR16: 28337208 | AS16: 147417695 | AT16: 136298810 | AU16: 10772512 | AV16: 346373 | AW16: 11118885 | AX16: 0 | AY16: 0 | AZ16: 147417695
A17: C09 | B17: 컴퓨터, 전자 및 광학기기 | C17: 181673 | D17: 13321 | E17: 179518 | F17: 41611 | G17: 229681 | H17: 822010 | I17: 730149 | J17: 94215 | K17: 473834 | L17: 1129751 | M17: 111091806 | N17: 14357957 | O17: 8884238 | P17: 11446256 | Q17: 150345 | R17: 2381775 | S17: 1173725 | T17: 449580 | U17: 1185699 | V17: 3095517 | W17: 872734 | X17: 1525087 | Y17: 10007238 | Z17: 604376 | AA17: 631498 | AB17: 13688295 | AC17: 1617811 | AD17: 1101557 | AE17: 1963339 | AF17: 4361931 | AG17: 523425 | AH17: 2615814 | AI17: 51754 | AJ17: 197677520 | AK17: 25091325 | AL17: 0 | AM17: 30155221 | AN17: 4162495 | AO17: 486519 | AP17: 0 | AQ17: 191050500 | AR17: 250946060 | AS17: 448623580 | AT17: 319811734 | AU17: 126034694 | AV17: 2777152 | AW17: 128811846 | AX17: 0 | AY17: 0 | AZ17: 448623580
A18: C10 | B18: 전기장비 | C18: 127130 | D18: 94350 | E18: 134004 | F18: 66778 | G18: 206216 | H18: 469945 | I18: 534499 | J18: 332306 | K18: 548446 | L18: 1395586 | M18: 8141816 | N18: 43904389 | O18: 8454471 | P18: 25867522 | Q18: 311865 | R18: 2037205 | S18: 2146060 | T18: 972943 | U18: 15485158 | V18: 1888909 | W18: 3253534 | X18: 2548408 | Y18: 3173256 | Z18: 368769 | AA18: 850238 | AB18: 8335414 | AC18: 2483438 | AD18: 982153 | AE18: 785992 | AF18: 597813 | AG18: 457683 | AH18: 3195593 | AI18: 11785 | AJ18: 140163674 | AK18: 11254160 | AL18: 0 | AM18: 15865555 | AN18: 302355 | AO18: -360625 | AP18: 0 | AQ18: 46805116 | AR18: 73866561 | AS18: 214030235 | AT18: 172753507 | AU18: 40326770 | AV18: 949958 | AW18: 41276728 | AX18: 0 | AY18: 0 | AZ18: 214030235
... A40: 9590 | B40: 중간투입계 | C40: 39166528 | D40: 3169491 | E40: 139457033 | F40: 57298913 | G40: 39700938 | H40: 143573392 | I40: 285565811 | J40: 37404675 | K40: 154477519 | L40: 92011168 | M40: 221737214 | N40: 135088695 | O40: 138660261 | P40: 269883451 | Q40: 21105797 | R40: 51124252 | S40: 120649253 | T40: 23032194 | U40: 199251516 | V40: 184102011 | W40: 125178243 | X40: 150662761 | Y40: 104063290 | Z40: 86678547 | AA40: 81055631 | AB40: 170997641 | AC40: 56091961 | AD40: 52243921 | AE40: 51016928 | AF40: 90583511 | AG40: 28521048 | AH40: 44847605 | AI40: 5019959 | AJ40: 3403421158 | AK40: 1203106723 | AL40: 428148599 | AM40: 642719412 | AN40: 114740934 | AO40: 8456630 | AP40: 2242835 | AQ40: 999815735 | AR40: 3399230868 | AS40: 6802652026 | AT40: 5786694739 | AU40: 990543488 | AV40: 25413799 | AW40: 1015957287 | AX40: 0 | AY40: 0 | AZ40: 6802652026
A41: 9610 | B41: 피용자보수 | C41: 7311007 | D41: 763130 | E41: 15128140 | F41: 6942083 | G41: 7714470 | H41: 1849380 | I41: 33024939 | J41: 5591739 | K41: 12874780 | L41: 22094377 | M41: 38330264 | N41: 18684449 | O41: 28417504 | P41: 24629085 | Q41: 4430442 | R41: 30392667 | S41: 7229124 | T41: 9301644 | U41: 108270135 | V41: 105848898 | W41: 45972783 | X41: 37217436 | Y41: 48448668 | Z41: 52077047 | AA41: 23572589 | AB41: 119508944 | AC41: 53019085 | AD41: 89879718 | AE41: 84723533 | AF41: 91542475 | AG41: 14325783 | AH41: 21260262 | AI41: 0 | AJ41: 1170376580
A42: 9621 | B42: 영업잉여 | C42: 20790625 | D42: 907945 | E42: 6246706 | F42: 1230526 | G42: 5894202 | H42: 10160438 | I42: 26725452 | J42: 2061144 | K42: 12662963 | L42: 15468441 | M42: -2691522 | N42: 509104 | O42: 5170759 | P42: 8332412 | Q42: 1502834 | R42: 4585557 | S42: -117531 | T42: 4067693 | U42: 6664903 | V42: 71028220 | W42: 16697450 | X42: 17852378 | Y42: 24101295 | Z42: 68918948 | AA42: 64506524 | AB42: 32838525 | AC42: 24595921 | AD42: 0 | AE42: 5753379 | AF42: 22888082 | AG42: 8967271 | AH42: 7606932 | AI42: 0 | AJ42: 495927576
A43: 9622 | B43: 고정자본소모 | C43: 6826925 | D43: 492826 | E43: 7184340 | F43: 2607552 | G43: 1594645 | H43: 3179003 | I43: 26775718 | J43: 4858806 | K43: 10685788 | L43: 5299685 | M43: 59980214 | N43: 16524948 | O43: 11389415 | P43: 27105345 | Q43: 906543 | R43: 10150938 | S43: 20286757 | T43: 5288608 | U43: 6766250 | V43: 18105570 | W43: 36332814 | X43: 5371797 | Y43: 35261097 | Z43: 12984833 | AA43: 69279349 | AB43: 28647148 | AC43: 7189528 | AD43: 60428502 | AE43: 12635621 | AF43: 13918268 | AG43: 6439170 | AH43: 4683288 | AI43: 0 | AJ43: 539181291
A44: 9630 | B44: 생산세(보조금공제) | C44: -27016 | D44: -6795 | E44: 14378726 | F44: 2081072 | G44: 1110431 | H44: 17800753 | I44: 4534298 | J44: 911160 | K44: 1198062 | L44: 1425139 | M44: 2455564 | N44: 1946311 | O44: 1845434 | P44: 7185378 | Q44: 997653 | R44: 548886 | S44: 3631197 | T44: 108881 | U44: 21285495 | V44: 17403973 | W44: -2966019 | X44: 12631432 | Y44: 6428467 | Z44: 10283809 | AA44: 33396994 | AB44: 3703102 | AC44: 3414461 | AD44: 3508 | AE44: 209536 | AF44: 218867 | AG44: 6447347 | AH44: 3202028 | AI44: 0 | AJ44: 177788134
A45: 9690 | B45: 부가가치계 | C45: 34901541 | D45: 2157106 | E45: 42937912 | F45: 12861233 | G45: 16313748 | H45: 32989574 | I45: 91060407 | J45: 13422849 | K45: 37421593 | L45: 44287642 | M45: 98074520 | N45: 37664812 | O45: 46823112 | P45: 67252220 | Q45: 7837472 | R45: 45678048 | S45: 31029547 | T45: 18766826 | U45: 142986783 | V45: 212386661 | W45: 96037028 | X45: 73073043 | Y45: 114239527 | Z45: 144264637 | AA45: 190755456 | AB45: 184697719 | AC45: 88218995 | AD45: 150311728 | AE45: 103322069 | AF45: 128567692 | AG45: 36179571 | AH45: 36752510 | AI45: 0 | AJ45: 2383273581
A46: 9790 | B46: 총투입계 | C46: 74068069 | D46: 5326597 | E46: 182394945 | F46: 70160146 | G46: 56014686 | H46: 176562966 | I46: 376626218 | J46: 50827524 | K46: 191899112 | L46: 136298810 | M46: 319811734 | N46: 172753507 | O46: 185483373 | P46: 337135671 | Q46: 28943269 | R46: 96802300 | S46: 151678800 | T46: 41799020 | U46: 342238299 | V46: 396488672 | W46: 221215271 | X46: 223735804 | Y46: 218302817 | Z46: 230943184 | AA46: 271811087 | AB46: 355695360 | AC46: 144310956 | AD46: 202555649 | AE46: 154338997 | AF46: 219151203 | AG46: 64700619 | AH46: 81600115 | AI46: 5019959 | AJ46: 5786694739
A47: GHG | B47: 탄소배출량(tco2eq.) | C47: 26208380 | D47: 2042881.6 | E47: 2065050 | F47: 4524770 | G47: 2843750 | H47: 36281630 | I47: 84687500 | J47: 35157346 | K47: 1.0253767e+08 | L47: 368275.38 | M47: 3829180 | N47: 123929.89 | O47: 6926970 | P47: 2362190 | Q47: 3595100.8 | R47: 1648578 | S47: 2.2933202e+08 | T47: 18172000 | U47: 1813020 | V47: 1433144.7 | W47: 1.0115978e+08 | X47: 2253065 | Y47: 101446.17 | Z47: 132046.07 | AA47: 236199.08 | AB47: 1892727 | AC47: 157565.49 | AD47: 6015859.9 | AE47: 2189527.8 | AF47: 1803187.2 | AG47: 373361.74 | AH47: 422069.89 | AI47: 0 | AJ47: =SUM(C47:AI47) -> 6.8269022e+08

Sheet 국산거래표_원본
A5: 상품 상품 | C5: A | D5: B | E5: C01 | F5: C02 | G5: C03 | H5: C04 | I5: C05 | J5: C06 | K5: C07 | L5: C08 | M5: C09 | N5: C10 | O5: C11 | P5: C12 | Q5: C13 | R5: C14 | S5: D | T5: E | U5: F | V5: G | W5: H | X5: I | Y5: J | Z5: K | AA5: L | AB5: M | AC5: N | AD5: O | AE5: P | AF5: Q | AG5: R | AH5: S | AI5: T | AJ5: 9090 | AK5: 9111 | AL5: 9112 | AM5: 9121 | AN5: 9122 | AO5: 9131 | AP5: 9132 | AQ5: 9140 | AR5: 9190 | AS5: 9290
C6: 농림수산품 | D6: 광산품 | E6: 음식료품 | F6: 섬유 및 가죽제품 | G6: 목재 및 종이, 인쇄 | H6: 석탄 및 석유제품 | I6: 화학제품 | J6: 비금속광물제품 | K6: 1차 금속제품 | L6: 금속가공제품 | M6: 컴퓨터, 전자 및 광학기기 | N6: 전기장비 | O6: 기계 및 장비 | P6: 운송장비 | Q6: 기타 제조업 제품 | R6: 제조임가공 및 산업용 장비 수리 | S6: 전력, 가스 및 증기 | T6: 수도, 폐기물처리 및 재활용서비스 | U6: 건설 | V6: 도소매 및 상품중개서비스 | W6: 운송서비스 | X6: 음식점 및 숙박서비스 | Y6: 정보통신 및 방송 서비스 | Z6: 금융 및 보험 서비스 | AA6: 부동산서비스 | AB6: 전문, 과학 및 기술 서비스 | AC6: 사업지원서비스 | AD6: 공공행정, 국방 및 사회보장 | AE6: 교육서비스 | AF6: 보건 및 사회복지 서비스 | AG6: 예술, 스포츠 및 여가 관련 서비스 | AH6: 기타 서비스 | AI6: 기타 | AJ6: 중간수요계 | AK6: 민간소비지출 (가계 및 가계봉사 비영리단체) | AL6: 정부소비지출 | AM6: 민간고정 자본형성 | AN6: 정부고정 자본형성 | AO6: 재고증감 | AP6: 귀중품 순취득 | AQ6: 수출 | AR6: 최종수요계 | AS6: 총수요계
A7: A | B7: 농림수산품 | C7: 3770505 | D7: 3469 | E7: 34517696 | F7: 38677 | G7: 277682 | H7: 4203 | I7: 555663 | J7: 3614 | K7: 6461 | L7: 7383 | M7: 7338 | N7: 2082 | O7: 6967 | P7: 2303 | Q7: 12637 | R7: 536115 | S7: 3751 | T7: 12739 | U7: 363655 | V7: 101278 | W7: 13100 | X7: 12633334 | Y7: 14422 | Z7: 11833 | AA7: 7087 | AB7: 68851 | AC7: 20544 | AD7: 314883 | AE7: 713174 | AF7: 800522 | AG7: 70580 | AH7: 72609 | AI7: 3405 | AJ7: 54978562 | AK7: 17086310 | AL7: 0 | AM7: 926994 | AN7: 683 | AO7: -72696 | AP7: 0 | AQ7: 1148216 | AR7: 19089507 | AS7: 74068069
A8: B | B8: 광산품 | C8: 2055 | D8: 2999 | E8: 41769 | F8: 2547 | G8: 11840 | H8: 112216 | I8: 373203 | J8: 3949468 | K8: 229276 | L8: 35343 | M8: 34809 | N8: 6206 | O8: 13252 | P8: 2213 | Q8: 2564 | R8: 18236 | S8: 127358 | T8: 53587 | U8: 249151 | V8: 0 | W8: 0 | X8: 12965 | Y8: 0 | Z8: 0 | AA8: 141 | AB8: 6011 | AC8: 13414 | AD8: 16750 | AE8: 1073 | AF8: 16722 | AG8: 2420 | AH8: 2421 | AI8: 34 | AJ8: 5340043 | AK8: 5091 | AL8: 0 | AM8: 0 | AN8: 0 | AO8: -183076 | AP8: 0 | AQ8: 164539 | AR8: -13446 | AS8: 5326597
A9: C01 | B9: 음식료품 | C9: 13273857 | D9: 16188 | E9: 23135036 | F9: 86468 | G9: 67764 | H9: -9926 | I9: 1348691 | J9: 32354 | K9: 78230 | L9: 106034 | M9: 28306 | N9: 23722 | O9: 80840 | P9: -15144 | Q9: 10822 | R9: 631680 | S9: 1119295 | T9: 75594 | U9: 29879 | V9: 2111745 | W9: 233156 | X9: 53046845 | Y9: 319298 | Z9: 166213 | AA9: 20617 | AB9: 1583400 | AC9: 714859 | AD9: 1174868 | AE9: 3190626 | AF9: 2680305 | AG9: 2613864 | AH9: 1099434 | AI9: 54767 | AJ9: 109129687 | AK9: 60359679 | AL9: 0 | AM9: 0 | AN9: 0 | AO9: -277115 | AP9: 0 | AQ9: 13182694 | AR9: 73265258 | AS9: 182394945
A10: C02 | B10: 섬유 및 가죽제품 | C10: 516322 | D10: 18761 | E10: 131097 | F10: 9447326 | G10: 469462 | H10: 99962 | I10: 1070192 | J10: 150174 | K10: 178752 | L10: 379901 | M10: 265419 | N10: 115994 | O10: 119809 | P10: 974041 | Q10: 1411763 | R10: 2466981 | S10: 44126 | T10: 232446 | U10: 78593 | V10: 1255250 | W10: 1794103 | X10: 1548791 | Y10: 247453 | Z10: 100674 | AA10: 173734 | AB10: 479977 | AC10: 1119697 | AD10: 646005 | AE10: 211196 | AF10: 838527 | AG10: 538987 | AH10: 836162 | AI10: 17447 | AJ10: 27979124 | AK10: 22360056 | AL10: 0 | AM10: 59349 | AN10: 35246 | AO10: 93928 | AP10: 0 | AQ10: 19632443 | AR10: 42181022 | AS10: 70160146
A11: C03 | B11: 목재 및 종이, 인쇄 | C11: 858139 | D11: 11121 | E11: 3523836 | F11: 218583 | G11: 12285532 | H11: 133424 | I11: 1854772 | J11: 387612 | K11: 234487 | L11: 982943 | M11: 146738 | N11: 483800 | O11: 332260 | P11: 97757 | Q11: 1409707 | R11: 394013 | S11: 426189 | T11: -7693 | U11: 4986871 | V11: 4184658 | W11: 1378727 | X11: 1993336 | Y11: 1909900 | Z11: 1584659 | AA11: 226739 | AB11: 5025693 | AC11: 614390 | AD11: 845929 | AE11: 949913 | AF11: 1277891 | AG11: 268691 | AH11: 828469 | AI11: 9881 | AJ11: 49858967 | AK11: 1312519 | AL11: 0 | AM11: 0 | AN11: 0 | AO11: 212872 | AP11: 0 | AQ11: 4630328 | AR11: 6155719 | AS11: 56014686
A12: C04 | B12: 석탄 및 석유제품 | C12: 1515963 | D12: 125960 | E12: 326179 | F12: 113399 | G12: 238255 | H12: 4806990 | I12: 18548314 | J12: 2257768 | K12: 507483 | L12: 449612 | M12: 77093 | N12: 466380 | O12: 306892 | P12: 408695 | Q12: 43843 | R12: 704980 | S12: 2470064 | T12: 678652 | U12: 4666910 | V12: 8836925 | W12: 15957783 | X12: 2950721 | Y12: 393549 | Z12: 139762 | AA12: 912283 | AB12: 4192860 | AC12: 894255 | AD12: 3333481 | AE12: 2184484 | AF12: 1490227 | AG12: 341918 | AH12: 912218 | AI12: 22523 | AJ12: 81276421 | AK12: 17658256 | AL12: 0 | AM12: 0 | AN12: 0 | AO12: 562201 | AP12: 0 | AQ12: 77066088 | AR12: 95286545 | AS12: 176562966
A13: C05 | B13: 화학제품 | C13: 4512625 | D13: 217552 | E13: 4252098 | F13: 5435495 | G13: 3512893 | H13: 2835512 | I13: 75443180 | J13: 1751720 | K13: 1645885 | L13: 7862792 | M13: 9877901 | N13: 9617046 | O13: 5052662 | P13: 19593987 | Q13: 2527837 | R13: 1787594 | S13: 2384812 | T13: 1951558 | U13: 11851540 | V13: 4975392 | W13: 1360977 | X13: 4735376 | Y13: 764740 | Z13: 119632 | AA13: 277331 | AB13: 9346112 | AC13: 3833427 | AD13: 1605326 | AE13: 1246078 | AF13: 23440952 | AG13: 730492 | AH13: 3262973 | AI13: 31874 | AJ13: 227845371 | AK13: 7116563 | AL13: 0 | AM13: 0 | AN13: 0 | AO13: 1249036 | AP13: 0 | AQ13: 140415248 | AR13: 148780847 | AS13: 376626218
A14: C06 | B14: 비금속광물제품 | C14: 36349 | D14: 8909 | E14: 866923 | F14: 29958 | G14: 57935 | H14: 128152 | I14: 1034800 | J14: 6026519 | K14: 2828197 | L14: 509833 | M14: 1263686 | N14: 892908 | O14: 355287 | P14: 1724611 | Q14: 192607 | R14: 133976 | S14: -162362 | T14: 186331 | U14: 27727818 | V14: 107592 | W14: 75336 | X14: 661954 | Y14: 13649 | Z14: 3732 | AA14: 84142 | AB14: 222048 | AC14: 226104 | AD14: 330613 | AE14: 141809 | AF14: 66266 | AG14: 141714 | AH14: 34688 | AI14: 4568 | AJ14: 45956652 | AK14: -69359 | AL14: 0 | AM14: 0 | AN14: 0 | AO14: 158903 | AP14: 0 | AQ14: 4781328 | AR14: 4870872 | AS14: 50827524
A15: C07 | B15: 1차 금속제품 | C15: 90703 | D15: 8189 | E15: 26239 | F15: -2016 | G15: 45297 | H15: 548043 | I15: 1432937 | J15: 880571 | K15: 33775453 | L15: 21994525 | M15: 4000083 | N15: 13934318 | O15: 11988557 | P15: 20302556 | Q15: 1504746 | R15: 987215 | S15: 378889 | T15: 162585 | U15: 23535608 | V15: -724 | W15: 14347 | X15: 27276 | Y15: -21236 | Z15: -69 | AA15: -536 | AB15: 379025 | AC15: 973 | AD15: 3089 | AE15: -19677 | AF15: 173780 | AG15: -4842 | AH15: -30110 | AI15: 9136 | AJ15: 136124930 | AK15: -741899 | AL15: 0 | AM15: -3134918 | AN15: -83309 | AO15: 315441 | AP15: 130731 | AQ15: 59288136 | AR15: 55774182 | AS15: 191899112
A16: C08 | B16: 금속가공제품 | C16: 76325 | D16: 112396 | E16: 2217143 | F16: 116512 | G16: 594802 | H16: 2872386 | I16: 2326406 | J16: 586542 | K16: 1481015 | L16: 18262217 | M16: 2003649 | N16: 4926314 | O16: 18984223 | P16: 17019521 | Q16: 1327694 | R16: 1130999 | S16: 798877 | T16: 546209 | U16: 24860415 | V16: 1065414 | W16: 731302 | X16: 1521590 | Y16: 248683 | Z16: 136263 | AA16: 198705 | AB16: 1106438 | AC16: 1089230 | AD16: 1582371 | AE16: 465853 | AF16: 353499 | AG16: 253202 | AH16: 928169 | AI16: 15794 | AJ16: 109940158 | AK16: 934850 | AL16: 0 | AM16: 6305296 | AN16: 1591651 | AO16: 150298 | AP16: 0 | AQ16: 17376557 | AR16: 26358652 | AS16: 136298810
A17: C09 | B17: 컴퓨터, 전자 및 광학기기 | C17: 180911 | D17: 13295 | E17: 178895 | F17: 40877 | G17: 222265 | H17: 811975 | I17: 622431 | J17: 87363 | K17: 457287 | L17: 1098790 | M17: 45724364 | N17: 8383439 | O17: 6399034 | P17: 6259350 | Q17: 137883 | R17: 2199819 | S17: 1052620 | T17: 442428 | U17: 897027 | V17: 2969353 | W17: 690604 | X17: 1505383 | Y17: 5684154 | Z17: 482548 | AA17: 606278 | AB17: 10579547 | AC17: 1523318 | AD17: 737465 | AE17: 1472022 | AF17: 1885952 | AG17: 498559 | AH17: 2190231 | AI17: 51754 | AJ17: 106087221 | AK17: 9881605 | AL17: 0 | AM17: 11175254 | AN17: 1544810 | AO17: 370986 | AP17: 0 | AQ17: 190751858 | AR17: 213724513 | AS17: 319811734
A18: C10 | B18: 전기장비 | C18: 126894 | D18: 94331 | E18: 133844 | F18: 64432 | G18: 205877 | H18: 468574 | I18: 472007 | J18: 328846 | K18: 471847 | L18: 1306810 | M18: 4221884 | N18: 27157868 | O18: 6662401 | P18: 19239436 | Q18: 298727 | R18: 1877102 | S18: 1705618 | T18: 971834 | U18: 13810541 | V18: 1878632 | W18: 2847236 | X18: 2514865 | Y18: 3111831 | Z18: 368380 | AA18: 846340 | AB18: 7997559 | AC18: 2423434 | AD18: 894011 | AE18: 777977 | AF18: 567661 | AG18: 450395 | AH18: 2598091 | AI18: 11785 | AJ18: 106907070 | AK18: 7237201 | AL18: 0 | AM18: 11864629 | AN18: 215296 | AO18: -275785 | AP18: 0 | AQ18: 46805096 | AR18: 65846437 | AS18: 172753507
... A40: 9590 | B40: 중간투입계 | C40: 36629418 | D40: 3132309 | E40: 113343360 | F40: 35375741 | G40: 33457207 | H40: 29230925 | I40: 188086537 | J40: 33179722 | K40: 87669754 | L40: 82319774 | M40: 128829304 | N40: 94361801 | O40: 112545716 | P40: 228228617 | Q40: 17968881 | R40: 48693679 | S40: 48196749 | T40: 22227137 | U40: 187124691 | V40: 171773776 | W40: 83129741 | X40: 138211903 | Y40: 84252364 | Z40: 78191811 | AA40: 79467442 | AB40: 157264645 | AC40: 51749545 | AD40: 45848739 | AE40: 48684605 | AF40: 76696145 | AG40: 26439064 | AH40: 41890955 | AI40: 5013554 | AJ40: 2619215611 | AK40: 1065594685 | AL40: 428148599 | AM40: 562479286 | AN40: 105301054 | AO40: 8131541 | AP40: 1393986 | AQ40: 996429977 | AR40: 3167479128 | AS40: 5786694739

Sheet 수입거래표원본
A5: 상품 상품 | C5: A | D5: B | E5: C01 | F5: C02 | G5: C03 | H5: C04 | I5: C05 | J5: C06 | K5: C07 | L5: C08 | M5: C09 | N5: C10 | O5: C11 | P5: C12 | Q5: C13 | R5: C14 | S5: D | T5: E | U5: F | V5: G | W5: H | X5: I | Y5: J | Z5: K | AA5: L | AB5: M | AC5: N | AD5: O | AE5: P | AF5: Q | AG5: R | AH5: S | AI5: T | AJ5: 9090 | AK5: 9111 | AL5: 9112 | AM5: 9121 | AN5: 9122 | AO5: 9131 | AP5: 9132 | AQ5: 9140 | AR5: 9190 | AS5: 9290
C6: 농림수산품 | D6: 광산품 | E6: 음식료품 | F6: 섬유 및 가죽제품 | G6: 목재 및 종이, 인쇄 | H6: 석탄 및 석유제품 | I6: 화학제품 | J6: 비금속광물제품 | K6: 1차 금속제품 | L6: 금속가공제품 | M6: 컴퓨터, 전자 및 광학기기 | N6: 전기장비 | O6: 기계 및 장비 | P6: 운송장비 | Q6: 기타 제조업 제품 | R6: 제조임가공 및 산업용 장비 수리 | S6: 전력, 가스 및 증기 | T6: 수도, 폐기물처리 및 재활용서비스 | U6: 건설 | V6: 도소매 및 상품중개서비스 | W6: 운송서비스 | X6: 음식점 및 숙박서비스 | Y6: 정보통신 및 방송 서비스 | Z6: 금융 및 보험 서비스 | AA6: 부동산서비스 | AB6: 전문, 과학 및 기술 서비스 | AC6: 사업지원서비스 | AD6: 공공행정, 국방 및 사회보장 | AE6: 교육서비스 | AF6: 보건 및 사회복지 서비스 | AG6: 예술, 스포츠 및 여가 관련 서비스 | AH6: 기타 서비스 | AI6: 기타 | AJ6: 중간수요계 | AK6: 민간소비지출 (가계 및 가계봉사 비영리단체) | AL6: 정부소비지출 | AM6: 민간고정 자본형성 | AN6: 정부고정 자본형성 | AO6: 재고증감 | AP6: 귀중품 순취득 | AQ6: 수출 | AR6: 최종수요계 | AS6: 총수요계
A7: A | B7: 농림수산품 | C7: 485806 | D7: 4 | E7: 10269411 | F7: 225767 | G7: 384167 | H7: 0 | I7: 770896 | J7: 0 | K7: 0 | L7: 0 | M7: 0 | N7: 0 | O7: 0 | P7: 129 | Q7: 2201 | R7: 6172 | S7: 0 | T7: 0 | U7: 39533 | V7: 2585 | W7: 0 | X7: 785607 | Y7: 0 | Z7: 0 | AA7: 0 | AB7: 4107 | AC7: 30 | AD7: 18414 | AE7: 3448 | AF7: 104448 | AG7: 1472 | AH7: 0 | AI7: 0 | AJ7: 13104197 | AK7: 3891020 | AL7: 0 | AM7: 78554 | AN7: 25 | AO7: -124101 | AP7: 0 | AQ7: 0 | AR7: 3845498 | AS7: 16949695
A8: B | B8: 광산품 | C8: 0 | D8: 0 | E8: 6933 | F8: 1045 | G8: 23183 | H8: 107955161 | I8: 8306004 | J8: 1258710 | K8: 33003679 | L8: 5139 | M8: 2774 | N8: 2583 | O8: 3102 | P8: 3589 | Q8: 1221 | R8: 58668 | S8: 68465917 | T8: 0 | U8: 29841 | V8: 0 | W8: 0 | X8: 2345 | Y8: 0 | Z8: 0 | AA8: 0 | AB8: 11233 | AC8: 0 | AD8: 16 | AE8: 0 | AF8: 0 | AG8: 0 | AH8: 0 | AI8: 0 | AJ8: 219141143 | AK8: 15221 | AL8: 0 | AM8: 0 | AN8: 0 | AO8: -1024984 | AP8: 0 | AQ8: 0 | AR8: -1009763 | AS8: 218131380
A9: C01 | B9: 음식료품 | C9: 217039 | D9: 0 | E9: 14132546 | F9: 1181363 | G9: 19998 | H9: 39673 | I9: 600263 | J9: 0 | K9: 0 | L9: 1 | M9: 152 | N9: 0 | O9: 1 | P9: 0 | Q9: 154 | R9: 10470 | S9: 547967 | T9: 0 | U9: 0 | V9: 25522 | W9: 4403 | X9: 9587420 | Y9: 2438 | Z9: 18 | AA9: 73 | AB9: 96884 | AC9: 15200 | AD9: 3950 | AE9: 359 | AF9: 646579 | AG9: 152751 | AH9: 61 | AI9: 0 | AJ9: 27285285 | AK9: 19637184 | AL9: 0 | AM9: 0 | AN9: 0 | AO9: -34940 | AP9: 0 | AQ9: 34138 | AR9: 19636382 | AS9: 46921667
A10: C02 | B10: 섬유 및 가죽제품 | C10: 174347 | D10: 0 | E10: 21486 | F10: 12494660 | G10: 141424 | H10: 234 | I10: 603928 | J10: 17137 | K10: 2780 | L10: 18756 | M10: 131172 | N10: 59861 | O10: 28893 | P10: 260543 | Q10: 292775 | R10: 214560 | S10: 2345 | T10: 28025 | U10: 105174 | V10: 538598 | W10: 151228 | X10: 31842 | Y10: 3202 | Z10: 6638 | AA10: 1880 | AB10: 74362 | AC10: 58739 | AD10: 43343 | AE10: 1459 | AF10: 80577 | AG10: 17470 | AH10: 27532 | AI10: 0 | AJ10: 15634970 | AK10: 22332792 | AL10: 0 | AM10: 39967 | AN10: 14749 | AO10: 144419 | AP10: 0 | AQ10: 545520 | AR10: 23077447 | AS10: 38712417
A11: C03 | B11: 목재 및 종이, 인쇄 | C11: 7878 | D11: 0 | E11: 191272 | F11: 196964 | G11: 4958971 | H11: 786 | I11: 142603 | J11: 38763 | K11: 8972 | L11: 78078 | M11: 149249 | N11: 87550 | O11: 21052 | P11: 22523 | Q11: 492175 | R11: 14371 | S11: 366563 | T11: 823 | U11: 1062856 | V11: 93547 | W11: 97844 | X11: 144017 | Y11: 96807 | Z11: 7682 | AA11: 1155 | AB11: 43992 | AC11: 17521 | AD11: 67204 | AE11: 10420 | AF11: 13359 | AG11: 39894 | AH11: 3034 | AI11: 0 | AJ11: 8477925 | AK11: 677764 | AL11: 0 | AM11: 0 | AN11: 0 | AO11: 34626 | AP11: 0 | AQ11: 0 | AR11: 712390 | AS11: 9190315
A12: C04 | B12: 석탄 및 석유제품 | C12: 37757 | D12: 1602 | E12: 42567 | F12: 68674 | G12: 67937 | H12: 3678754 | I12: 25346933 | J12: 151699 | K12: 213878 | L12: 78341 | M12: 31162 | N12: 45968 | O12: 30864 | P12: 64171 | Q12: 2031 | R12: 308039 | S12: 1641796 | T12: 12310 | U12: 20644 | V12: 666955 | W12: 8671116 | X12: 527023 | Y12: 10762 | Z12: 6497 | AA12: 5743 | AB12: 187182 | AC12: 24291 | AD12: 21693 | AE12: 414541 | AF12: 73957 | AG12: 11857 | AH12: 181330 | AI12: 0 | AJ12: 42648074 | AK12: 2351959 | AL12: 0 | AM12: 0 | AN12: 0 | AO12: 122942 | AP12: 0 | AQ12: 0 | AR12: 2474901 | AS12: 45122975
A13: C05 | B13: 화학제품 | C13: 823131 | D13: 1746 | E13: 468348 | F13: 1384234 | G13: 290277 | H13: 702283 | I13: 53919657 | J13: 791765 | K13: 1457010 | L13: 1146298 | M13: 10310680 | N13: 7787804 | O13: 517828 | P13: 2199954 | Q13: 470344 | R13: 195467 | S13: 32359 | T13: 213275 | U13: 370668 | V13: 313587 | W13: 199697 | X13: 122969 | Y13: 47614 | Z13: 1970 | AA13: 237 | AB13: 932094 | AC13: 158761 | AD13: 9449 | AE13: 24208 | AF13: 9505479 | AG13: 27678 | AH13: 465733 | AI13: 82 | AJ13: 94892686 | AK13: 9275297 | AL13: 0 | AM13: 0 | AN13: 0 | AO13: 786835 | AP13: 0 | AQ13: 1521940 | AR13: 11584072 | AS13: 106476758
A14: C06 | B14: 비금속광물제품 | C14: 268 | D14: 9 | E14: 38333 | F14: 11626 | G14: 1622 | H14: 25759 | I14: 586505 | J14: 1596074 | K14: 437502 | L14: 103158 | M14: 723481 | N14: 913729 | O14: 156003 | P14: 575874 | Q14: 64422 | R14: 69580 | S14: 10357 | T14: 1262 | U14: 2035888 | V14: 11889 | W14: 1409 | X14: 80193 | Y14: 12 | Z14: 164 | AA14: 60 | AB14: 118951 | AC14: 55 | AD14: 494 | AE14: 956 | AF14: 5107 | AG14: 18 | AH14: 21458 | AI14: 0 | AJ14: 7592218 | AK14: 250632 | AL14: 0 | AM14: 0 | AN14: 0 | AO14: 28484 | AP14: 0 | AQ14: 0 | AR14: 279116 | AS14: 7871334
A15: C07 | B15: 1차 금속제품 | C15: 408 | D15: 7 | E15: 0 | F15: 4713 | G15: 423 | H15: 14064 | I15: 1955775 | J15: 22979 | K15: 28789189 | L15: 4180771 | M15: 2708037 | N15: 4376195 | O15: 1504504 | P15: 6067366 | Q15: 261104 | R15: 82173 | S15: 35069 | T15: 8142 | U15: 2165701 | V15: 11 | W15: 117848 | X15: 0 | Y15: 0 | Z15: 0 | AA15: 2 | AB15: 56161 | AC15: 216 | AD15: 20 | AE15: 0 | AF15: 192309 | AG15: 0 | AH15: 309 | AI15: 0 | AJ15: 52543496 | AK15: 10179 | AL15: 0 | AM15: 0 | AN15: 0 | AO15: -197121 | AP15: 33102 | AQ15: 0 | AR15: -153840 | AS15: 52389656
A16: C08 | B16: 금속가공제품 | C16: 1615 | D16: 5465 | E16: 153937 | F16: 131663 | G16: 14605 | H16: 27749 | I16: 347215 | J16: 80661 | K16: 92724 | L16: 2667595 | M16: 701714 | N16: 298453 | O16: 784745 | P16: 1813669 | Q16: 163305 | R16: 157203 | S16: 70256 | T16: 1812 | U16: 615883 | V16: 81840 | W16: 346465 | X16: 220397 | Y16: 3027 | Z16: 5250 | AA16: 2117 | AB16: 140927 | AC16: 12213 | AD16: 159772 | AE16: 8294 | AF16: 2317 | AG16: 2422 | AH16: 25019 | AI16: 0 | AJ16: 9140329 | AK16: 952367 | AL16: 0 | AM16: 222504 | AN16: 779287 | AO16: 24398 | AP16: 0 | AQ16: 0 | AR16: 1978556 | AS16: 11118885
A17: C09 | B17: 컴퓨터, 전자 및 광학기기 | C17: 762 | D17: 26 | E17: 623 | F17: 734 | G17: 7416 | H17: 10035 | I17: 107718 | J17: 6852 | K17: 16547 | L17: 30961 | M17: 65367442 | N17: 5974518 | O17: 2485204 | P17: 5186906 | Q17: 12462 | R17: 181956 | S17: 121105 | T17: 7152 | U17: 288672 | V17: 126164 | W17: 182130 | X17: 19704 | Y17: 4323084 | Z17: 121828 | AA17: 25220 | AB17: 3108748 | AC17: 94493 | AD17: 364092 | AE17: 491317 | AF17: 2475979 | AG17: 24866 | AH17: 425583 | AI17: 0 | AJ17: 91590299 | AK17: 15209720 | AL17: 0 | AM17: 18979967 | AN17: 2617685 | AO17: 115533 | AP17: 0 | AQ17: 298642 | AR17: 37221547 | AS17: 128811846
A18: C10 | B18: 전기장비 | C18: 236 | D18: 19 | E18: 160 | F18: 2346 | G18: 339 | H18: 1371 | I18: 62492 | J18: 3460 | K18: 76599 | L18: 88776 | M18: 3919932 | N18: 16746521 | O18: 1792070 | P18: 6628086 | Q18: 13138 | R18: 160103 | S18: 440442 | T18: 1109 | U18: 1674617 | V18: 10277 | W18: 406298 | X18: 33543 | Y18: 61425 | Z18: 389 | AA18: 3898 | AB18: 337855 | AC18: 60004 | AD18: 88142 | AE18: 8015 | AF18: 30152 | AG18: 7288 | AH18: 597502 | AI18: 0 | AJ18: 33256604 | AK18: 4016959 | AL18: 0 | AM18: 4000926 | AN18: 87059 | AO18: -84840 | AP18: 0 | AQ18: 20 | AR18: 8020124 | AS18: 41276728
... A40: 9590 | B40: 중간투입계 | C40: 2537110 | D40: 37182 | E40: 26113673 | F40: 21923172 | G40: 6243731 | H40: 114342467 | I40: 97479274 | J40: 4224953 | K40: 66807765 | L40: 9691394 | M40: 92907910 | N40: 40726894 | O40: 26114545 | P40: 41654834 | Q40: 3136916 | R40: 2430573 | S40: 72452504 | T40: 805057 | U40: 12126825 | V40: 12328235 | W40: 42048502 | X40: 12450858 | Y40: 19810926 | Z40: 8486736 | AA40: 1588189 | AB40: 13732996 | AC40: 4342416 | AD40: 6395182 | AE40: 2332323 | AF40: 13887366 | AG40: 2081984 | AH40: 2956650 | AI40: 6405 | AJ40: 784205547 | AK40: 137512038 | AL40: 0 | AM40: 80240126 | AN40: 9439880 | AO40: 325089 | AP40: 848849 | AQ40: 3385758 | AR40: 231751740 | AS40: 1015957287

Sheet 총투입계수(A)
A1: 투입산출표_총투입계수표(2023년 가격)
A2: 2023년
A3: 생산자가격
A5: 상품 상품 | C5: A | D5: B | E5: C01 | F5: C02 | G5: C03 | H5: C04 | I5: C05 | J5: C06 | K5: C07 | L5: C08 | M5: C09 | N5: C10 | O5: C11 | P5: C12 | Q5: C13 | R5: C14 | S5: D | T5: E | U5: F | V5: G | W5: H | X5: I | Y5: J | Z5: K | AA5: L | AB5: M | AC5: N | AD5: O | AE5: P | AF5: Q | AG5: R | AH5: S | AI5: T | AJ5: 9090
C6: 농림수산품 | D6: 광산품 | E6: 음식료품 | F6: 섬유 및 가죽제품 | G6: 목재 및 종이, 인쇄 | H6: 석탄 및 석유제품 | I6: 화학제품 | J6: 비금속광물제품 | K6: 1차 금속제품 | L6: 금속가공제품 | M6: 컴퓨터, 전자 및 광학기기 | N6: 전기장비 | O6: 기계 및 장비 | P6: 운송장비 | Q6: 기타 제조업제품 | R6: 제조임가공 및 산업용 장비 수리 | S6: 전력, 가스 및 증기 | T6: 수도, 폐기물처리 및 재활용서비스 | U6: 건설 | V6: 도소매 및 상품중개서비스 | W6: 운송서비스 | X6: 음식점 및 숙박서비스 | Y6: 정보통신 및 방송서비스 | Z6: 금융 및 보험서비스 | AA6: 부동산서비스 | AB6: 전문, 과학 및 기술 서비스 | AC6: 사업지원서비스 | AD6: 공공행정, 국방 및 사회보장 | AE6: 교육서비스 | AF6: 보건 및 사회복지서비스 | AG6: 예술, 스포츠 및 여가 관련 서비스 | AH6: 기타 서비스 | AI6: 기타 | AJ6: 중간수요계
A7: A | B7: 농림수산품 | C7: 0.057464857 | D7: 0.00065201103 | E7: 0.24555015 | F7: 0.0037691484 | G7: 0.011815633 | H7: 2.3804539e-05 | I7: 0.0035222163 | J7: 7.1103208e-05 | K7: 3.3668733e-05 | L7: 5.4167751e-05 | M7: 2.2944749e-05 | N7: 1.2051854e-05 | O7: 3.7561318e-05 | P7: 7.2137131e-06 | Q7: 0.00051265806 | R7: 0.0056020053 | S7: 2.472989e-05 | T7: 0.00030476791 | U7: 0.0011780914 | V7: 0.00026195704 | W7: 5.9218335e-05 | X7: 0.059976726 | Y7: 6.6064196e-05 | Z7: 5.123771e-05 | AA7: 2.6073256e-05 | AB7: 0.00020511372 | AC7: 0.00014256714 | AD7: 0.0016454589 | AE7: 0.0046431687 | AF7: 0.004129432 | AG7: 0.0011136215 | AH7: 0.00088981492 | AI7: 0.00067829239 | AJ7: 0.011765397
A8: B | B8: 광산품 | C8: 2.7744749e-05 | D8: 0.00056302363 | E8: 0.00026701398 | F8: 5.1197157e-05 | G8: 0.00062524674 | H8: 0.6120614 | I8: 0.023044617 | J8: 0.10246767 | K8: 0.17317931 | L8: 0.0002970092 | M8: 0.00011751601 | N8: 5.0875957e-05 | O8: 8.8169628e-05 | P8: 1.7209689e-05 | Q8: 0.00013077307 | R8: 0.00079444393 | S8: 0.45222717 | T8: 0.0012820157 | U8: 0.00081519807 | V8: 0 | W8: 0 | X8: 6.8428923e-05 | Y8: 0 | Z8: 0 | AA8: 5.1874264e-07 | AB8: 4.8479688e-05 | AC8: 9.2952056e-05 | AD8: 8.2772315e-05 | AE8: 6.9522287e-06 | AF8: 7.6303483e-05 | AG8: 3.7403042e-05 | AH8: 2.9669076e-05 | AI8: 6.7729637e-06 | AJ8: 0.038792643
A9: C01 | B9: 음식료품 | C9: 0.18214186 | D9: 0.0030390886 | E9: 0.20432355 | F9: 0.01807053 | G9: 0.0015667677 | H9: 0.00016847814 | I9: 0.0051747699 | J9: 0.00063654488 | K9: 0.00040766213 | L9: 0.00077795984 | M9: 8.8983602e-05 | N9: 0.00013731704 | O9: 0.0004358396 | P9: -4.4919602e-05 | Q9: 0.00037922461 | R9: 0.0066336234 | S9: 0.010992057 | T9: 0.0018085113 | U9: 8.7304665e-05 | V9: 0.0053904869 | W9: 0.0010738816 | X9: 0.27994744 | Y9: 0.001473806 | Z9: 0.00071979176 | AA9: 7.6119044e-05 | AB9: 0.0047239413 | AC9: 0.0050589298 | AD9: 0.0058197241 | AE9: 0.02067517 | AF9: 0.01518077 | AG9: 0.042760256 | AH9: 0.013474184 | AI9: 0.01090985 | AJ9: 0.023573902
A10: C02 | B10: 섬유 및 가죽제품 | C10: 0.0093247874 | D10: 0.0035221362 | E10: 0.00083655279 | F10: 0.31274145 | G10: 0.010905819 | H10: 0.00056748027 | I10: 0.0044450437 | J10: 0.0032917401 | K10: 0.00094597624 | L10: 0.0029248751 | M10: 0.0012400765 | N10: 0.0010179533 | O10: 0.00080169989 | P10: 0.0036619797 | Q10: 0.05889238 | R10: 0.027701212 | S10: 0.00030637769 | T10: 0.0062315097 | U10: 0.00053695627 | V10: 0.0045243361 | W10: 0.0087938368 | X10: 0.0070647298 | Y10: 0.0011481987 | Z10: 0.0004646684 | AA10: 0.00064608844 | AB10: 0.0015584656 | AC10: 0.0081659496 | AD10: 0.0034032524 | AE10: 0.0013778436 | AF10: 0.0041939263 | AG10: 0.0086004896 | AH10: 0.01058447 | AI10: 0.0034755264 | AJ10: 0.0075369612
A11: C03 | B11: 목재 및 종이, 인쇄 | C11: 0.011692177 | D11: 0.0020878246 | E11: 0.020368481 | F11: 0.0059228355 | G11: 0.30785682 | H11: 0.00076012543 | I11: 0.005303335 | J11: 0.0083886636 | K11: 0.0012686823 | L11: 0.0077845214 | M11: 0.00092550388 | N11: 0.0033073135 | O11: 0.0019048176 | P11: 0.00035677032 | Q11: 0.065710684 | R11: 0.0042187427 | S11: 0.0052265181 | T11: -0.00016435792 | U11: 0.017676943 | V11: 0.010790233 | W11: 0.006674815 | X11: 0.0095530217 | Y11: 0.0091923092 | Z11: 0.0068949469 | AA11: 0.0008384279 | AB11: 0.014252885 | AC11: 0.0043788151 | AD11: 0.0045080599 | AE11: 0.0062222317 | AF11: 0.0058920507 | AG11: 0.0047694289 | AH11: 0.010189973 | AI11: 0.0019683428 | AJ11: 0.010081211
A12: C04 | B12: 석탄 및 석유제품 | C12: 0.020976921 | D12: 0.023948123 | E12: 0.0020216898 | F12: 0.0025951058 | G12: 0.0054662808 | H12: 0.048060724 | I12: 0.11654857 | J12: 0.047404768 | K12: 0.0037590638 | L12: 0.0038734968 | M12: 0.00033849602 | N12: 0.0029657748 | O12: 0.0018209503 | P12: 0.0014025985 | Q12: 0.0015849626 | R12: 0.010464824 | S12: 0.027108996 | T12: 0.016530579 | U12: 0.013696755 | V12: 0.023970117 | W12: 0.11133453 | X12: 0.015543976 | Y12: 0.001852065 | Z12: 0.00063331161 | AA12: 0.0033774413 | AB12: 0.012314026 | AC12: 0.0063650469 | AD12: 0.016564208 | AE12: 0.016839717 | AF12: 0.0071374648 | AG12: 0.0054678766 | AH12: 0.013401305 | AI12: 0.00448669 | AJ12: 0.021415419
A13: C05 | B13: 화학제품 | C13: 0.072038546 | D13: 0.041170376 | E13: 0.025880355 | F13: 0.097202321 | G13: 0.067895944 | H13: 0.020037016 | I13: 0.34347804 | J13: 0.050041489 | K13: 0.016169408 | L13: 0.066098083 | M13: 0.063126455 | N13: 0.10074962 | O13: 0.030032288 | P13: 0.064644423 | Q13: 0.1035882 | R13: 0.020485681 | S13: 0.015936116 | T13: 0.051791477 | U13: 0.035712566 | V13: 0.013339546 | W13: 0.0070550012 | X13: 0.021714651 | Y13: 0.0037212255 | Z13: 0.00052654509 | AA13: 0.0010211798 | AB13: 0.028896092 | AC13: 0.02766379 | AD13: 0.0079720067 | AE13: 0.0082304928 | AF13: 0.15033653 | AG13: 0.011718126 | AH13: 0.045694862 | AI13: 0.006365789 | AJ13: 0.055772435
A14: C06 | B14: 비금속광물제품 | C14: 0.00049436958 | D14: 0.0016742397 | E14: 0.0049631639 | F14: 0.00059270116 | G14: 0.001063239 | H14: 0.00087170602 | I14: 0.0043048118 | J14: 0.14996979 | K14: 0.017017791 | L14: 0.0044974054 | M14: 0.0062135525 | N14: 0.010457889 | O14: 0.0027565274 | P14: 0.0068236179 | Q14: 0.0088804413 | R14: 0.0021028013 | S14: -0.0010021506 | T14: 0.004487976 | U14: 0.086967783 | V14: 0.00030134783 | W14: 0.00034692451 | X14: 0.0033170686 | Y14: 6.2578212e-05 | Z14: 1.686995e-05 | AA14: 0.00030978133 | AB14: 0.00095868273 | AC14: 0.0015671645 | AD14: 0.0016346471 | AE14: 0.00092500925 | AF14: 0.00032567925 | AG14: 0.0021905818 | AH14: 0.00068806276 | AI14: 0.00090996759 | AJ14: 0.0092537921
A15: C07 | B15: 1차 금속제품 | C15: 0.0012300982 | D15: 0.0015386935 | E15: 0.00014385815 | F15: 3.8440627e-05 | G15: 0.00081621452 | H15: 0.0031836065 | I15: 0.0089975467 | J15: 0.017776786 | K15: 0.32602882 | L15: 0.19204347 | M15: 0.020975215 | N15: 0.10599213 | O15: 0.072745394 | P15: 0.078217538 | Q15: 0.061010731 | R15: 0.011047134 | S15: 0.0027291751 | T15: 0.0040844738 | U15: 0.0750977 | V15: -1.7982859e-06 | W15: 0.00059758533 | X15: 0.00012191165 | Y15: -9.7277719e-05 | Z15: -2.9877478e-07 | AA15: -1.9645998e-06 | AB15: 0.0012234796 | AC15: 8.2391527e-06 | AD15: 1.5348868e-05 | AE15: -0.00012749208 | AF15: 0.0016704859 | AG15: -7.4836997e-05 | AH15: -0.00036520782 | AI15: 0.0018199352 | AJ15: 0.032603833
A16: C08 | B16: 금속가공제품 | C16: 0.0010522753 | D16: 0.022126885 | E16: 0.012999702 | F16: 0.0035372646 | G16: 0.010879415 | H16: 0.0164255 | I16: 0.0070988712 | J16: 0.013126805 | K16: 0.0082008665 | L16: 0.15355829 | M16: 0.0084592362 | N16: 0.030244058 | O16: 0.10658081 | P16: 0.055862347 | Q16: 0.051514533 | R16: 0.013307556 | S16: 0.0057300888 | T16: 0.013110858 | U16: 0.074440231 | V16: 0.0028935354 | W16: 0.004872028 | X16: 0.0077859107 | Y16: 0.0011530314 | Z16: 0.0006127611 | AA16: 0.00073882932 | AB16: 0.0035068352 | AC16: 0.0076324281 | AD16: 0.0086008117 | AE16: 0.003072114 | AF16: 0.0016236096 | AG16: 0.0039508741 | AH16: 0.011681209 | AI16: 0.0031462408 | AJ16: 0.020578325
A17: C09 | B17: 컴퓨터, 전자 및 광학기기 | C17: 0.0024527843 | D17: 0.0025008462 | E17: 0.00098422684 | F17: 0.000593086 | G17: 0.0041003711 | H17: 0.0046556196 | I17: 0.0019386569 | J17: 0.0018536217 | K17: 0.0024691829 | L17: 0.0082887811 | M17: 0.34736626 | N17: 0.083112391 | O17: 0.04789776 | P17: 0.033951483 | Q17: 0.005194472 | R17: 0.024604529 | S17: 0.0077382271 | T17: 0.010755755 | U17: 0.0034645421 | V17: 0.0078073277 | W17: 0.0039451797 | X17: 0.0068164638 | Y17: 0.045841085 | Z17: 0.00261699 | AA17: 0.0023232974 | AB17: 0.038483198 | AC17: 0.01121059 | AD17: 0.0054382932 | AE17: 0.012720952 | AF17: 0.019903751 | AG17: 0.0080899535 | AH17: 0.032056499 | AI17: 0.010309646 | AJ17: 0.034160696
A18: C10 | B18: 전기장비 | C18: 0.0017163941 | D18: 0.017712998 | E18: 0.00073469141 | F18: 0.00095179391 | G18: 0.0036814631 | H18: 0.0026616284 | I18: 0.0014191763 | J18: 0.0065379144 | K18: 0.0028579913 | L18: 0.010239165 | M18: 0.025458153 | N18: 0.2541447 | O18: 0.045580749 | P18: 0.076727336 | Q18: 0.010775044 | R18: 0.021045006 | S18: 0.014148714 | T18: 0.023276694 | U18: 0.045246713 | V18: 0.0047640932 | W18: 0.014707547 | X18: 0.011390256 | Y18: 0.014536029 | Z18: 0.0015967953 | AA18: 0.0031280475 | AB18: 0.023434138 | AC18: 0.017208936 | AD18: 0.0048488058 | AE18: 0.0050926338 | AF18: 0.0027278563 | AG18: 0.0070738581 | AH18: 0.039161624 | AI18: 0.0023476287 | AJ18: 0.024221716
... A46: 9790 | B46: 총투입계 | C46: 1 | D46: 1 | E46: 1 | F46: 1 | G46: 1 | H46: 1 | I46: 1 | J46: 1 | K46: 1 | L46: 1 | M46: 1 | N46: 1 | O46: 1 | P46: 1 | Q46: 1 | R46: 1 | S46: 1 | T46: 1 | U46: 1 | V46: 1 | W46: 1 | X46: 1 | Y46: 1 | Z46: 1 | AA46: 1 | AB46: 1 | AC46: 1 | AD46: 1 | AE46: 1 | AF46: 1 | AG46: 1 | AH46: 1 | AI46: 1 | AJ46: 1

Sheet A표_총거래표(생산자)_new
A1: 투입산출표_총거래표(2023년 가격)
A2: 2023년 | K2: 채워 넣어야하는 값
A3: 생산자가격 | K3: =cases2!B6-cases2!D43-SUM(cases2!D44:D46) -> 350
A4: 단위 : 백만원
A5: 상품 상품 | C5: A | D5: B | E5: C01 | F5: C02 | G5: C03 | H5: C04 | I5: C05 | M5: C06 | N5: C07 | O5: C08 | P5: C09 | Q5: C10 | R5: C11 | S5: C12 | T5: C13 | U5: C14 | V5: D | W5: E | X5: F | Y5: G | Z5: H | AA5: I | AB5: J | AC5: K | AD5: L | AE5: M | AF5: N | AG5: O | AH5: P | AI5: Q | AJ5: R | AK5: S | AL5: T | AM5: 9090 | AN5: 9111 | AO5: 9112 | AP5: 9121 | AQ5: 9122 | AR5: 9131 | AS5: 9132 | AT5: 9140 | AU5: 9190 | AV5: 9290 | AW5: 9310 | AX5: 9321 | AY5: 9322 | AZ5: 9329 | BA5: 9331 | BB5: 9332 | BC5: 9390
C6: 농림수산품 | D6: 광산품 | E6: 음식료품 | F6: 섬유 및 가죽제품 | G6: 목재 및 종이, 인쇄 | H6: 석탄 및 석유제품 | I6: 화학제품 | J6: 3.기존 C05 조정 | K6: 1.투입계수 적용 | L6: 2.총액맞추기 | M6: 비금속광물제품 | N6: 1차 금속제품 | O6: 금속가공제품 | P6: 컴퓨터, 전자 및 광학기기 | Q6: 전기장비 | R6: 기계 및 장비 | S6: 운송장비 | T6: 기타 제조업제품 | U6: 제조임가공 및 산업용 장비 수리 | V6: 전력, 가스 및 증기 | W6: 수도, 폐기물처리 및 재활용서비스 | X6: 건설 | Y6: 도소매 및 상품중개서비스 | Z6: 운송서비스 | AA6: 음식점 및 숙박서비스 | AB6: 정보통신 및 방송서비스 | AC6: 금융 및 보험서비스 | AD6: 부동산서비스 | AE6: 전문, 과학 및 기술 서비스 | AF6: 사업지원서비스 | AG6: 공공행정, 국방 및 사회보장 | AH6: 교육서비스 | AI6: 보건 및 사회복지서비스 | AJ6: 예술, 스포츠 및 여가 관련 서비스 | AK6: 기타 서비스 | AL6: 기타 | AM6: 중간수요계 | AN6: 민간소비지출 (가계 및 가계봉사 비영리단체) | AO6: 정부소비지출 | AP6: 민간고정 자본형성 | AQ6: 정부고정 자본형성 | AR6: 재고증감 | AS6: 귀중품 순취득 | AT6: 수출 | AU6: 최종수요계 | AV6: 총수요계 | AW6: 총산출 | AX6: 수입 | AY6: 생산물세(수입) | AZ6: 수입계 | BA6: 도소매마진 | BB6: 화물운임 | BC6: 총공급계
A7: A | B7: 농림수산품 | C7: 4256311 | D7: 3473 | E7: 44787107 | F7: 264444 | G7: 661849 | H7: 4203 | I7: 1326559 | J7: =I7-L7 -> 1326557.3 | K7: ='총투입계수(A)'!I7*cases2!$B$6 -> 3.5222163 | L7: =K7/SUM($K$7:$K$18,$K$20:$K$22,$K$24:$K$39)*$K$3 -> 1.7124297 | M7: 3614 | N7: 6461 | O7: 7383 | P7: 7338 | Q7: 2082 | R7: 6967 | S7: 2432 | T7: 14838 | U7: 542287 | V7: 3751 | W7: 12739 | X7: 403188 | Y7: 103863 | Z7: 13100 | AA7: 13418941 | AB7: 14422 | AC7: 11833 | AD7: 7087 | AE7: 72958 | AF7: 20574 | AG7: 333297 | AH7: 716622 | AI7: 904970 | AJ7: 72052 | AK7: 72609 | AL7: 3405 | AM7: 68082759 | AN7: 20977330 | AO7: 0 | AP7: 1005548 | AQ7: 708 | AR7: -196797 | AS7: 0 | AT7: 1148216 | AU7: 22935005 | AV7: 91017764 | AW7: 74068069 | AX7: 16390900 | AY7: 558795 | AZ7: 16949695 | BA7: 0 | BB7: 0 | BC7: 91017764
A8: B | B8: 광산품 | C8: 2055 | D8: 2999 | E8: 48702 | F8: 3592 | G8: 35023 | H8: 108067377 | I8: 8679207 | J8: =I8-L8 -> 8679195.8 | K8: ='총투입계수(A)'!I8*cases2!$B$6 -> 23.044617 | L8: =K8/SUM($K$7:$K$18,$K$20:$K$22,$K$24:$K$39)*$K$3 -> 11.203823 | M8: 5208178 | N8: 33232955 | O8: 40482 | P8: 37583 | Q8: 8789 | R8: 16354 | S8: 5802 | T8: 3785 | U8: 76904 | V8: 68593275 | W8: 53587 | X8: 278992 | Y8: 0 | Z8: 0 | AA8: 15310 | AB8: 0 | AC8: 0 | AD8: 141 | AE8: 17244 | AF8: 13414 | AG8: 16766 | AH8: 1073 | AI8: 16722 | AJ8: 2420 | AK8: 2421 | AL8: 34 | AM8: 224481186 | AN8: 20312 | AO8: 0 | AP8: 0 | AQ8: 0 | AR8: -1208060 | AS8: 0 | AT8: 164539 | AU8: -1023209 | AV8: 223457977 | AW8: 5326597 | AX8: 213114501 | AY8: 5016879 | AZ8: 218131380 | BA8: 0 | BB8: 0 | BC8: 223457977
A9: C01 | B9: 음식료품 | C9: 13490896 | D9: 16188 | E9: 37267582 | F9: 1267831 | G9: 87762 | H9: 29747 | I9: 1948954 | J9: =I9-L9 -> 1948951.5 | K9: ='총투입계수(A)'!I9*cases2!$B$6 -> 5.1747699 | L9: =K9/SUM($K$7:$K$18,$K$20:$K$22,$K$24:$K$39)*$K$3 -> 2.5158675 | M9: 32354 | N9: 78230 | O9: 106035 | P9: 28458 | Q9: 23722 | R9: 80841 | S9: -15144 | T9: 10976 | U9: 642150 | V9: 1667262 | W9: 75594 | X9: 29879 | Y9: 2137267 | Z9: 237559 | AA9: 62634265 | AB9: 321736 | AC9: 166231 | AD9: 20690 | AE9: 1680284 | AF9: 730059 | AG9: 1178818 | AH9: 3190985 | AI9: 3326884 | AJ9: 2766615 | AK9: 1099495 | AL9: 54767 | AM9: 136414972 | AN9: 79996863 | AO9: 0 | AP9: 0 | AQ9: 0 | AR9: -312055 | AS9: 0 | AT9: 13216832 | AU9: 92901640 | AV9: 229316612 | AW9: 182394945 | AX9: 42877588 | AY9: 4044079 | AZ9: 46921667 | BA9: 0 | BB9: 0 | BC9: 229316612
A10: C02 | B10: 섬유 및 가죽제품 | C10: 690669 | D10: 18761 | E10: 152583 | F10: 21941986 | G10: 610886 | H10: 100196 | I10: 1674120 | J10: =I10-L10 -> 1674117.8 | K10: ='총투입계수(A)'!I10*cases2!$B$6 -> 4.4450437 | L10: =K10/SUM($K$7:$K$18,$K$20:$K$22,$K$24:$K$39)*$K$3 -> 2.1610896 | M10: 167311 | N10: 181532 | O10: 398657 | P10: 396591 | Q10: 175855 | R10: 148702 | S10: 1234584 | T10: 1704538 | U10: 2681541 | V10: 46471 | W10: 260471 | X10: 183767 | Y10: 1793848 | Z10: 1945331 | AA10: 1580633 | AB10: 250655 | AC10: 107312 | AD10: 175614 | AE10: 554339 | AF10: 1178436 | AG10: 689348 | AH10: 212655 | AI10: 919104 | AJ10: 556457 | AK10: 863694 | AL10: 17447 | AM10: 43614094 | AN10: 44692848 | AO10: 0 | AP10: 99316 | AQ10: 49995 | AR10: 238347 | AS10: 0 | AT10: 20177963 | AU10: 65258469 | AV10: 108872563 | AW10: 70160146 | AX10: 35870234 | AY10: 2842183 | AZ10: 38712417 | BA10: 0 | BB10: 0 | BC10: 108872563
A11: C03 | B11: 목재 및 종이, 인쇄 | C11: 866017 | D11: 11121 | E11: 3715108 | F11: 415547 | G11: 17244503 | H11: 134210 | I11: 1997375 | J11: =I11-L11 -> 1997372.4 | K11: ='총투입계수(A)'!I11*cases2!$B$6 -> 5.303335 | L11: =K11/SUM($K$7:$K$18,$K$20:$K$22,$K$24:$K$39)*$K$3 -> 2.5783733 | M11: 426375 | N11: 243459 | O11: 1061021 | P11: 295987 | Q11: 571350 | R11: 353312 | S11: 120280 | T11: 1901882 | U11: 408384 | V11: 792752 | W11: -6870 | X11: 6049727 | Y11: 4278205 | Z11: 1476571 | AA11: 2137353 | AB11: 2006707 | AC11: 1592341 | AD11: 227894 | AE11: 5069685 | AF11: 631911 | AG11: 913133 | AH11: 960333 | AI11: 1291250 | AJ11: 308585 | AK11: 831503 | AL11: 9881 | AM11: 58336892 | AN11: 1990283 | AO11: 0 | AP11: 0 | AQ11: 0 | AR11: 247498 | AS11: 0 | AT11: 4630328 | AU11: 6868109 | AV11: 65205001 | AW11: 56014686 | AX11: 8967588 | AY11: 222727 | AZ11: 9190315 | BA11: 0 | BB11: 0 | BC11: 65205001
A12: C04 | B12: 석탄 및 석유제품 | C12: 1553720 | D12: 127562 | E12: 368746 | F12: 182073 | G12: 306192 | H12: 8485744 | I12: 43895247 | J12: =I12-L12 -> 43895190 | K12: ='총투입계수(A)'!I12*cases2!$B$6 -> 116.54857 | L12: =K12/SUM($K$7:$K$18,$K$20:$K$22,$K$24:$K$39)*$K$3 -> 56.663537 | M12: 2409467 | N12: 721361 | O12: 527953 | P12: 108255 | Q12: 512348 | R12: 337756 | S12: 472866 | T12: 45874 | U12: 1013019 | V12: 4111860 | W12: 690962 | X12: 4687554 | Y12: 9503880 | Z12: 24628899 | AA12: 3477744 | AB12: 404311 | AC12: 146259 | AD12: 918026 | AE12: 4380042 | AF12: 918546 | AG12: 3355174 | AH12: 2599025 | AI12: 1564184 | AJ12: 353775 | AK12: 1093548 | AL12: 22523 | AM12: 123924495 | AN12: 20010215 | AO12: 0 | AP12: 0 | AQ12: 0 | AR12: 685143 | AS12: 0 | AT12: 77066088 | AU12: 97761446 | AV12: 221685941 | AW12: 176562966 | AX12: 44170694 | AY12: 952281 | AZ12: 45122975 | BA12: 0 | BB12: 0 | BC12: 221685941
A13: C05 | B13: 화학제품 | C13: 5335756 | D13: 219298 | E13: 4720446 | F13: 6819729 | G13: 3803170 | H13: 3537795 | I13: 129362837 | J13: =I13-L13 -> 1.2936267e+08 | K13: ='총투입계수(A)'!I13*cases2!$B$6 -> 343.47804 | L13: =K13/SUM($K$7:$K$18,$K$20:$K$22,$K$24:$K$39)*$K$3 -> 166.99202 | M13: 2543485 | N13: 3102895 | O13: 9009090 | P13: 20188581 | Q13: 17404850 | R13: 5570490 | S13: 21793941 | T13: 2998181 | U13: 1983061 | V13: 2417171 | W13: 2164833 | X13: 12222208 | Y13: 5288979 | Z13: 1560674 | AA13: 4858345 | AB13: 812354 | AC13: 121602 | AD13: 277568 | AE13: 10278206 | AF13: 3992188 | AG13: 1614775 | AH13: 1270286 | AI13: 32946431 | AJ13: 758170 | AK13: 3728706 | AL13: 31956 | AM13: 322738057 | AN13: 16391860 | AO13: 0 | AP13: 0 | AQ13: 0 | AR13: 2035871 | AS13: 0 | AT13: 141937188 | AU13: 160364919 | AV13: 483102976 | AW13: 376626218 | AX13: 104125789 | AY13: 2350969 | AZ13: 106476758 | BA13: 0 | BB13: 0 | BC13: 483102976
A14: C06 | B14: 비금속광물제품 | C14: 36617 | D14: 8918 | E14: 905256 | F14: 41584 | G14: 59557 | H14: 153911 | I14: 1621305 | J14: =I14-L14 -> 1621302.9 | K14: ='총투입계수(A)'!I14*cases2!$B$6 -> 4.3048118 | L14: =K14/SUM($K$7:$K$18,$K$20:$K$22,$K$24:$K$39)*$K$3 -> 2.0929117 | M14: 7622593 | N14: 3265699 | O14: 612991 | P14: 1987167 | Q14: 1806637 | R14: 511290 | S14: 2300485 | T14: 257029 | U14: 203556 | V14: -152005 | W14: 187593 | X14: 29763706 | Y14: 119481 | Z14: 76745 | AA14: 742147 | AB14: 13661 | AC14: 3896 | AD14: 84202 | AE14: 340999 | AF14: 226159 | AG14: 331107 | AH14: 142765 | AI14: 71373 | AJ14: 141732 | AK14: 56146 | AL14: 4568 | AM14: 53548870 | AN14: 181273 | AO14: 0 | AP14: 0 | AQ14: 0 | AR14: 187387 | AS14: 0 | AT14: 4781328 | AU14: 5149988 | AV14: 58698858 | AW14: 50827524 | AX14: 7600425 | AY14: 270909 | AZ14: 7871334 | BA14: 0 | BB14: 0 | BC14: 58698858
A15: C07 | B15: 1차 금속제품 | C15: 91111 | D15: 8196 | E15: 26239 | F15: 2697 | G15: 45720 | H15: 562107 | I15: 3388712 | J15: =I15-L15 -> 3388707.6 | K15: ='총투입계수(A)'!I15*cases2!$B$6 -> 8.9975467 | L15: =K15/SUM($K$7:$K$18,$K$20:$K$22,$K$24:$K$39)*$K$3 -> 4.3744237 | M15: 903550 | N15: 62564642 | O15: 26175296 | P15: 6708120 | Q15: 18310513 | R15: 13493061 | S15: 26369922 | T15: 1765850 | U15: 1069388 | V15: 413958 | W15: 170727 | X15: 25701309 | Y15: -713 | Z15: 132195 | AA15: 27276 | AB15: -21236 | AC15: -69 | AD15: -534 | AE15: 435186 | AF15: 1189 | AG15: 3109 | AH15: -19677 | AI15: 366089 | AJ15: -4842 | AK15: -29801 | AL15: 9136 | AM15: 188668426 | AN15: -731720 | AO15: 0 | AP15: -3134918 | AQ15: -83309 | AR15: 118320 | AS15: 163833 | AT15: 59288136 | AU15: 55620342 | AV15: 244288768 | AW15: 191899112 | AX15: 52115731 | AY15: 273925 | AZ15: 52389656 | BA15: 0 | BB15: 0 | BC15: 244288768
A16: C08 | B16: 금속가공제품 | C16: 77940 | D16: 117861 | E16: 2371080 | F16: 248175 | G16: 609407 | H16: 2900135 | I16: 2673621 | J16: =I16-L16 -> 2673617.5 | K16: ='총투입계수(A)'!I16*cases2!$B$6 -> 7.0988712 | L16: =K16/SUM($K$7:$K$18,$K$20:$K$22,$K$24:$K$39)*$K$3 -> 3.4513263 | M16: 667203 | N16: 1573739 | O16: 20929812 | P16: 2705363 | Q16: 5224767 | R16: 19768968 | S16: 18833190 | T16: 1490999 | U16: 1288202 | V16: 869133 | W16: 548021 | X16: 25476298 | Y16: 1147254 | Z16: 1077767 | AA16: 1741987 | AB16: 251710 | AC16: 141513 | AD16: 200822 | AE16: 1247365 | AF16: 1101443 | AG16: 1742143 | AH16: 474147 | AI16: 355816 | AJ16: 255624 | AK16: 953188 | AL16: 15794 | AM16: 119080487 | AN16: 1887217 | AO16: 0 | AP16: 6527800 | AQ16: 2370938 | AR16: 174696 | AS16: 0 | AT16: 17376557 | AU16: 28337208 | AV16: 147417695 | AW16: 136298810 | AX16: 10772512 | AY16: 346373 | AZ16: 11118885 | BA16: 0 | BB16: 0 | BC16: 147417695
A17: C09 | B17: 컴퓨터, 전자 및 광학기기 | C17: 181673 | D17: 13321 | E17: 179518 | F17: 41611 | G17: 229681 | H17: 822010 | I17: 730149 | J17: =I17-L17 -> 730148.06 | K17: ='총투입계수(A)'!I17*cases2!$B$6 -> 1.9386569 | L17: =K17/SUM($K$7:$K$18,$K$20:$K$22,$K$24:$K$39)*$K$3 -> 0.94253541 | M17: 94215 | N17: 473834 | O17: 1129751 | P17: 111091806 | Q17: 14357957 | R17: 8884238 | S17: 11446256 | T17: 150345 | U17: 2381775 | V17: 1173725 | W17: 449580 | X17: 1185699 | Y17: 3095517 | Z17: 872734 | AA17: 1525087 | AB17: 10007238 | AC17: 604376 | AD17: 631498 | AE17: 13688295 | AF17: 1617811 | AG17: 1101557 | AH17: 1963339 | AI17: 4361931 | AJ17: 523425 | AK17: 2615814 | AL17: 51754 | AM17: 197677520 | AN17: 25091325 | AO17: 0 | AP17: 30155221 | AQ17: 4162495 | AR17: 486519 | AS17: 0 | AT17: 191050500 | AU17: 250946060 | AV17: 448623580 | AW17: 319811734 | AX17: 126034694 | AY17: 2777152 | AZ17: 128811846 | BA17: 0 | BB17: 0 | BC17: 448623580
A18: C10 | B18: 전기장비 | C18: 127130 | D18: 94350 | E18: 134004 | F18: 66778 | G18: 206216 | H18: 469945 | I18: 534499 | J18: =I18-L18 -> 534498.31 | K18: ='총투입계수(A)'!I18*cases2!$B$6 -> 1.4191763 | L18: =K18/SUM($K$7:$K$18,$K$20:$K$22,$K$24:$K$39)*$K$3 -> 0.68997456 | M18: 332306 | N18: 548446 | O18: 1395586 | P18: 8141816 | Q18: 43904389 | R18: 8454471 | S18: 25867522 | T18: 311865 | U18: 2037205 | V18: 2146060 | W18: 972943 | X18: 15485158 | Y18: 1888909 | Z18: 3253534 | AA18: 2548408 | AB18: 3173256 | AC18: 368769 | AD18: 850238 | AE18: 8335414 | AF18: 2483438 | AG18: 982153 | AH18: 785992 | AI18: 597813 | AJ18: 457683 | AK18: 3195593 | AL18: 11785 | AM18: 140163674 | AN18: 11254160 | AO18: 0 | AP18: 15865555 | AQ18: 302355 | AR18: -360625 | AS18: 0 | AT18: 46805116 | AU18: 73866561 | AV18: 214030235 | AW18: 172753507 | AX18: 40326770 | AY18: 949958 | AZ18: 41276728 | BA18: 0 | BB18: 0 | BC18: 214030235
A19: C11 | B19: 기계 및 장비 | C19: 129919 | D19: 120796 | E19: 347920 | F19: 31863 | G19: 94508 | H19: 1382092 | I19: 788628 | J19: =I19-L19 -> 788528 | K19: 100 | L19: =K19 -> 100 | M19: 155078 | N19: 734140 | O19: 2600060 | P19: 1519513 | Q19: 1498282 | R19: 39011415 | S19: 9746821 | T19: 56187 | U19: 1472837 | V19: 1127344 | W19: 1179355 | X19: 11223089 | Y19: 650365 | Z19: 989282 | AA19: 370234 | AB19: 128658 | AC19: 50603 | AD19: 337724 | AE19: 1323848 | AF19: 383679 | AG19: 539228 | AH19: 368941 | AI19: 247391 | AJ19: 151440 | AK19: 135707 | AL19: 6506 | AM19: 78903453 | AN19: 2796216 | AO19: 0 | AP19: 90764774 | AQ19: 1006484 | AR19: 229139 | AS19: 0 | AT19: 70735546 | AU19: 165532159 | AV19: 244435612 | AW19: 185483373 | AX19: 57666958 | AY19: 1285281 | AZ19: 58952239 | BA19: 0 | BB19: 0 | BC19: 244435612
